{
  "affected_release": [
    {
      "product_name": "Red Hat Enterprise Linux 9",
      "release_date": "2023-11-07T00:00:00Z",
      "advisory": "RHSA-2023:6494",
      "package": "python3.11-0:3.11.5-1.el9_3",
      "cpe": "cpe:/a:redhat:enterprise_linux:9"
    }
  ],
  "package_state": [
    {
      "product_name": "Red Hat Enterprise Linux 6",
      "fix_state": "Not affected",
      "package_name": "python",
      "cpe": "cpe:/o:redhat:enterprise_linux:6"
    },
    {
      "product_name": "Red Hat Enterprise Linux 7",
      "fix_state": "Not affected",
      "package_name": "python",
      "cpe": "cpe:/o:redhat:enterprise_linux:7"
    },
    {
      "product_name": "Red Hat Enterprise Linux 7",
      "fix_state": "Not affected",
      "package_name": "python3",
      "cpe": "cpe:/o:redhat:enterprise_linux:7"
    },
    {
      "product_name": "Red Hat Enterprise Linux 8",
      "fix_state": "Not affected",
      "package_name": "python27:2.7/python2",
      "cpe": "cpe:/o:redhat:enterprise_linux:8"
    },
    {
      "product_name": "Red Hat Enterprise Linux 8",
      "fix_state": "Not affected",
      "package_name": "python3",
      "cpe": "cpe:/o:redhat:enterprise_linux:8"
    },
    {
      "product_name": "Red Hat Enterprise Linux 8",
      "fix_state": "Affected",
      "package_name": "python3.11",
      "cpe": "cpe:/o:redhat:enterprise_linux:8"
    },
    {
      "product_name": "Red Hat Enterprise Linux 8",
      "fix_state": "Not affected",
      "package_name": "python36:3.6/python36",
      "cpe": "cpe:/o:redhat:enterprise_linux:8"
    },
    {
      "product_name": "Red Hat Enterprise Linux 8",
      "fix_state": "Not affected",
      "package_name": "python39:3.9/python39",
      "cpe": "cpe:/o:redhat:enterprise_linux:8"
    },
    {
      "product_name": "Red Hat Enterprise Linux 9",
      "fix_state": "Not affected",
      "package_name": "python3.9",
      "cpe": "cpe:/o:redhat:enterprise_linux:9"
    },
    {
      "product_name": "Red Hat Software Collections",
      "fix_state": "Not affected",
      "package_name": "rh-python38-python",
      "cpe": "cpe:/a:redhat:rhel_software_collections:3"
    }
  ],
  "threat_severity": "Moderate",
  "public_date": "2023-08-23T00:00:00Z",
  "bugzilla": {
    "description": "file path truncation at \\0 characters",
    "id": "2235795",
    "url": "https://bugzilla.redhat.com/show_bug.cgi?id=2235795"
  },
  "cvss": {
    "cvss_base_score": "",
    "cvss_scoring_vector": "",
    "status": ""
  },
  "cvss3": {
    "cvss3_base_score": "7.5",
    "cvss3_scoring_vector": "CVSS:3.1/AV:N/AC:L/PR:N/UI:N/S:U/C:N/I:H/A:N",
    "status": "verified"
  },
  "iava": "",
  "cwe": "CWE-158",
  "statement": "Python versions prior to 3.11.0 are not affected by this flaw.",
  "acknowledgement": "",
  "name": "CVE-2023-41105",
  "document_distribution": "",
  "details": [
    "An issue was discovered in Python 3.11 through 3.11.4. If a path containing '\\0' bytes is passed to os.path.normpath(), the path will be truncated unexpectedly at the first '\\0' byte. There are plausible cases in which an application would have rejected a filename for security reasons in Python 3.10.x or earlier, but that filename is no longer rejected in Python 3.11.x.",
    "Python 3.11 os.path.normpath() function is vulnerable to path truncation if a null byte is inserted in the middle of passed path. This may result in bypass of allow lists if implemented before the verification of the path."
  ],
  "references": [
    "https://www.cve.org/CVERecord?id=CVE-2023-41105\nhttps://nvd.nist.gov/vuln/detail/CVE-2023-41105\nhttps://mail.python.org/archives/list/security-announce@python.org/thread/D6CDW3ZZC5D444YGL3VQUY6D4ECMCQLD/"
  ]
}