{
  "affected_release": null,
  "package_state": [
    {
      "product_name": "Red Hat Enterprise Linux 6",
      "fix_state": "Not affected",
      "package_name": "kernel",
      "cpe": "cpe:/o:redhat:enterprise_linux:6"
    },
    {
      "product_name": "Red Hat Enterprise Linux 7",
      "fix_state": "Not affected",
      "package_name": "kernel",
      "cpe": "cpe:/o:redhat:enterprise_linux:7"
    },
    {
      "product_name": "Red Hat Enterprise Linux 7",
      "fix_state": "Not affected",
      "package_name": "kernel-rt",
      "cpe": "cpe:/o:redhat:enterprise_linux:7"
    },
    {
      "product_name": "Red Hat Enterprise Linux 8",
      "fix_state": "Not affected",
      "package_name": "kernel",
      "cpe": "cpe:/o:redhat:enterprise_linux:8"
    },
    {
      "product_name": "Red Hat Enterprise Linux 8",
      "fix_state": "Not affected",
      "package_name": "kernel-rt",
      "cpe": "cpe:/o:redhat:enterprise_linux:8"
    },
    {
      "product_name": "Red Hat Enterprise Linux 9",
      "fix_state": "Not affected",
      "package_name": "kernel",
      "cpe": "cpe:/o:redhat:enterprise_linux:9"
    },
    {
      "product_name": "Red Hat Enterprise Linux 9",
      "fix_state": "Not affected",
      "package_name": "kernel-rt",
      "cpe": "cpe:/o:redhat:enterprise_linux:9"
    }
  ],
  "threat_severity": "Moderate",
  "public_date": "2023-06-20T00:00:00Z",
  "bugzilla": {
    "description": "out-of-bounds read in read_descriptors",
    "id": "2221039",
    "url": "https://bugzilla.redhat.com/show_bug.cgi?id=2221039"
  },
  "cvss": {
    "cvss_base_score": "",
    "cvss_scoring_vector": "",
    "status": ""
  },
  "cvss3": {
    "cvss3_base_score": "4.6",
    "cvss3_scoring_vector": "CVSS:3.1/AV:P/AC:L/PR:N/UI:N/S:U/C:N/I:N/A:H",
    "status": "draft"
  },
  "iava": "",
  "cwe": "CWE-125",
  "statement": "No Red Hat products are affected by this flaw, as the upstream commit that introduced this flaw (45bf39f) is not included in any shipping kernel release.",
  "acknowledgement": "",
  "name": "CVE-2023-37453",
  "document_distribution": "",
  "details": [
    "An issue was discovered in the USB subsystem in the Linux kernel through 6.4.2. There is an out-of-bounds and crash in read_descriptors in drivers/usb/core/sysfs.c."
  ],
  "references": [
    "https://www.cve.org/CVERecord?id=CVE-2023-37453\nhttps://nvd.nist.gov/vuln/detail/CVE-2023-37453"
  ]
}