{
  "affected_release": null,
  "package_state": [
    {
      "product_name": "Red Hat Ansible Automation Platform 2",
      "fix_state": "Not affected",
      "package_name": "python-django",
      "cpe": "cpe:/a:redhat:ansible_automation_platform:2"
    },
    {
      "product_name": "Red Hat Certification for Red Hat Enterprise Linux 7",
      "fix_state": "Under investigation",
      "package_name": "python-django",
      "cpe": "cpe:/a:redhat:certifications:1::el7"
    },
    {
      "product_name": "Red Hat OpenStack Platform 16.1",
      "fix_state": "Under investigation",
      "package_name": "python-django20",
      "cpe": "cpe:/a:redhat:openstack:16.1"
    },
    {
      "product_name": "Red Hat OpenStack Platform 16.2",
      "fix_state": "Under investigation",
      "package_name": "python-django20",
      "cpe": "cpe:/a:redhat:openstack:16.2"
    },
    {
      "product_name": "Red Hat OpenStack Platform 17.1",
      "fix_state": "Under investigation",
      "package_name": "python-django",
      "cpe": "cpe:/a:redhat:openstack:17.1"
    },
    {
      "product_name": "Red Hat Satellite 6",
      "fix_state": "Not affected",
      "package_name": "python-django",
      "cpe": "cpe:/a:redhat:satellite:6"
    },
    {
      "product_name": "Red Hat Storage 3",
      "fix_state": "Under investigation",
      "package_name": "python-django",
      "cpe": "cpe:/a:redhat:storage:3"
    },
    {
      "product_name": "Red Hat Update Infrastructure 4 for Cloud Providers",
      "fix_state": "Not affected",
      "package_name": "python-django",
      "cpe": "cpe:/a:redhat:rhui:4::el8"
    }
  ],
  "threat_severity": "Moderate",
  "public_date": "2023-11-01T07:00:00Z",
  "bugzilla": {
    "description": "Potential denial of service vulnerability in UsernameField on Windows",
    "id": "2247097",
    "url": "https://bugzilla.redhat.com/show_bug.cgi?id=2247097"
  },
  "cvss": {
    "cvss_base_score": "",
    "cvss_scoring_vector": "",
    "status": ""
  },
  "cvss3": {
    "cvss3_base_score": "",
    "cvss3_scoring_vector": "",
    "status": ""
  },
  "iava": "",
  "cwe": "",
  "statement": "",
  "acknowledgement": "",
  "name": "CVE-2023-46695",
  "document_distribution": "",
  "details": [
    "No description is available for this CVE."
  ],
  "references": [
    "https://www.cve.org/CVERecord?id=CVE-2023-46695\nhttps://nvd.nist.gov/vuln/detail/CVE-2023-46695"
  ]
}