{
  "affected_release": null,
  "package_state": [
    {
      "product_name": "Red Hat Ansible Automation Platform 2",
      "fix_state": "Affected",
      "package_name": "python-django",
      "cpe": "cpe:/a:redhat:ansible_automation_platform:2"
    },
    {
      "product_name": "Red Hat Certification for Red Hat Enterprise Linux 7",
      "fix_state": "Affected",
      "package_name": "python-django",
      "cpe": "cpe:/a:redhat:certifications:1::el7"
    },
    {
      "product_name": "Red Hat OpenStack Platform 16.1",
      "fix_state": "Out of support scope",
      "package_name": "python-django20",
      "cpe": "cpe:/a:redhat:openstack:16.1"
    },
    {
      "product_name": "Red Hat OpenStack Platform 16.2",
      "fix_state": "Out of support scope",
      "package_name": "python-django20",
      "cpe": "cpe:/a:redhat:openstack:16.2"
    },
    {
      "product_name": "Red Hat OpenStack Platform 17.0",
      "fix_state": "Out of support scope",
      "package_name": "python-django",
      "cpe": "cpe:/a:redhat:openstack:17.0"
    },
    {
      "product_name": "Red Hat OpenStack Platform 17.1",
      "fix_state": "Out of support scope",
      "package_name": "python-django",
      "cpe": "cpe:/a:redhat:openstack:17.1"
    },
    {
      "product_name": "Red Hat Satellite 6",
      "fix_state": "Affected",
      "package_name": "python-django",
      "cpe": "cpe:/a:redhat:satellite:6"
    },
    {
      "product_name": "Red Hat Storage 3",
      "fix_state": "Affected",
      "package_name": "python-django",
      "cpe": "cpe:/a:redhat:storage:3"
    },
    {
      "product_name": "Red Hat Update Infrastructure 4 for Cloud Providers",
      "fix_state": "Affected",
      "package_name": "python-django",
      "cpe": "cpe:/a:redhat:rhui:4::el8"
    }
  ],
  "threat_severity": "Moderate",
  "public_date": "2023-09-04T00:00:00Z",
  "bugzilla": {
    "description": "Potential denial of service vulnerability in  ``django.utils.encoding.uri_to_iri()``",
    "id": "2237258",
    "url": "https://bugzilla.redhat.com/show_bug.cgi?id=2237258"
  },
  "cvss": {
    "cvss_base_score": "",
    "cvss_scoring_vector": "",
    "status": ""
  },
  "cvss3": {
    "cvss3_base_score": "6.5",
    "cvss3_scoring_vector": "CVSS:3.1/AV:N/AC:L/PR:N/UI:N/S:U/C:N/I:L/A:L",
    "status": "draft"
  },
  "iava": "",
  "cwe": "CWE-400",
  "statement": "",
  "acknowledgement": "",
  "name": "CVE-2023-41164",
  "document_distribution": "",
  "details": [
    "An uncontrolled resource consumption vulnerability was found in Django. Feeding certain inputs with a very large number of Unicode characters to the URI to IRI encoder function can lead to a denial of service."
  ],
  "references": [
    "https://www.cve.org/CVERecord?id=CVE-2023-41164\nhttps://nvd.nist.gov/vuln/detail/CVE-2023-41164\nhttps://www.djangoproject.com/weblog/2023/sep/04/security-releases/"
  ]
}