{
  "affected_release": null,
  "package_state": [
    {
      "product_name": "Red Hat Enterprise Linux 6",
      "fix_state": "Under investigation",
      "package_name": "python",
      "cpe": "cpe:/o:redhat:enterprise_linux:6"
    },
    {
      "product_name": "Red Hat Enterprise Linux 7",
      "fix_state": "Under investigation",
      "package_name": "python",
      "cpe": "cpe:/o:redhat:enterprise_linux:7"
    },
    {
      "product_name": "Red Hat Enterprise Linux 7",
      "fix_state": "Under investigation",
      "package_name": "python3",
      "cpe": "cpe:/o:redhat:enterprise_linux:7"
    },
    {
      "product_name": "Red Hat Enterprise Linux 8",
      "fix_state": "Under investigation",
      "package_name": "gimp:flatpak/python2",
      "cpe": "cpe:/o:redhat:enterprise_linux:8"
    },
    {
      "product_name": "Red Hat Enterprise Linux 8",
      "fix_state": "Under investigation",
      "package_name": "inkscape:flatpak/python2",
      "cpe": "cpe:/o:redhat:enterprise_linux:8"
    },
    {
      "product_name": "Red Hat Enterprise Linux 8",
      "fix_state": "Under investigation",
      "package_name": "python27:2.7/python2",
      "cpe": "cpe:/o:redhat:enterprise_linux:8"
    },
    {
      "product_name": "Red Hat Enterprise Linux 8",
      "fix_state": "Under investigation",
      "package_name": "python3",
      "cpe": "cpe:/o:redhat:enterprise_linux:8"
    },
    {
      "product_name": "Red Hat Enterprise Linux 8",
      "fix_state": "Under investigation",
      "package_name": "python3.11",
      "cpe": "cpe:/o:redhat:enterprise_linux:8"
    },
    {
      "product_name": "Red Hat Enterprise Linux 8",
      "fix_state": "Under investigation",
      "package_name": "python36:3.6/python36",
      "cpe": "cpe:/o:redhat:enterprise_linux:8"
    },
    {
      "product_name": "Red Hat Enterprise Linux 8",
      "fix_state": "Under investigation",
      "package_name": "python39:3.9/python39",
      "cpe": "cpe:/o:redhat:enterprise_linux:8"
    },
    {
      "product_name": "Red Hat Enterprise Linux 9",
      "fix_state": "Under investigation",
      "package_name": "python3.11",
      "cpe": "cpe:/o:redhat:enterprise_linux:9"
    },
    {
      "product_name": "Red Hat Enterprise Linux 9",
      "fix_state": "Under investigation",
      "package_name": "python3.9",
      "cpe": "cpe:/o:redhat:enterprise_linux:9"
    },
    {
      "product_name": "Red Hat Software Collections",
      "fix_state": "Under investigation",
      "package_name": "rh-python38-python",
      "cpe": "cpe:/a:redhat:rhel_software_collections:3"
    }
  ],
  "threat_severity": "Moderate",
  "public_date": "2023-08-22T00:00:00Z",
  "bugzilla": {
    "description": "python: use after free in heappushpop() of heapq module",
    "id": "2249755",
    "url": "https://bugzilla.redhat.com/show_bug.cgi?id=2249755"
  },
  "cvss": {
    "cvss_base_score": "",
    "cvss_scoring_vector": "",
    "status": ""
  },
  "cvss3": {
    "cvss3_base_score": "",
    "cvss3_scoring_vector": "",
    "status": ""
  },
  "iava": "",
  "cwe": "CWE-416",
  "statement": "",
  "acknowledgement": "",
  "name": "CVE-2022-48560",
  "document_distribution": "",
  "details": [
    "A use-after-free exists in Python through 3.9 via heappushpop in heapq."
  ],
  "references": [
    "https://www.cve.org/CVERecord?id=CVE-2022-48560\nhttps://nvd.nist.gov/vuln/detail/CVE-2022-48560"
  ]
}